Workbook

Sheet Assumptions
A1: HOUSEHOLD FINANCIAL MODEL — ASSUMPTIONS & INPUTS
A2: Blue cells = change these | All $ in AUD | As at May 2026
A4: INCOME | B4: James / Household | C4: Sue value
A5: James — base salary (gross) | B5: 190000 | D5: Source: Payslip 2026
A6: Sue — base salary (gross) | B6: 200000 | D6: Source: Payslip 2026
A7: Employer super rate | B7: 0.125 | D7: 12.5% — both
A8: James — bonus rate (of base) | B8: 0.15 | D8: 15% of base salary
A9: James — bonus probability | B9: 0.8 | D9: ~80% hit rate historically
A10: Annual salary growth (both) | B10: 0.03 | D10: 3% award increase p.a.
A12: PROPERTIES
A13: Alexander St — current value | B13: 900000 | D13: Seddon VIC — owner occupied
A14: Alexander St — annual growth | B14: 0.04 | D14: Melbourne long-run avg
A15: Alexander St — loan balance | B15: 170106 | D15: As at May 2026
A16: Alexander St — interest rate | B16: 0.0589 | D16: Variable — NAB Choice Package
A17: Alexander St — min repayment/mth | B17: 1752.13 | D17: Confirmed from NAB app 29 Jul 2026
A18: Alexander St — extra repayment/mth | B18: 1497.87 | D18: ACTUAL: $750/wk total = $3,250/mth. Set to 0 to model the recommendation
A19: Alexander St — offset balance | B19: 17350 | D19: As at May 2026
A20: Walter St — current value | B20: 800000 | D20: Sue's property — owner occupied
A21: Walter St — annual growth | B21: 0.04 | D21: Melbourne long-run avg
A22: Walter St — loan balance | B22: 459344 | D22: As at May 2026
A23: Walter St — interest rate | B23: 0.0599 | D23: Variable — NAB 100% Offset
A24: Walter St — min repayment/mth | B24: 2982.56 | D24: P&I — loan ends Aug 2054
A25: Walter St — offset balance | B25: 200014 | D25: As at May 2026 — household savings
A27: SUPERANNUATION
A28: James — super balance | B28: 448141 | D28: Plum NAB Staff MySuper — Apr 2026
A29: James — super investment return (net of fees) | B29: 0.07 | D29: Default MySuper; upgrade to 8.5% if switch to high growth
A30: Sue — super balance | B30: 350000 | D30: Estimate — May 2026
A31: Sue — super investment return (net of fees) | B31: 0.07 | D31: Assumed similar balanced option
A32: James — annual salary sacrifice | B32: 0 | D32: Set to remaining cap space (check MyGov first)
A33: Sue — annual salary sacrifice | B33: 0 | D33: $5,000 cap space available FY2026
A35: SHARE PORTFOLIO
A36: NAB shares — current value | B36: 139086 | D36: 3,492 shares @ $39.83 — Computershare DRP
A37: Other shares — current value | B37: 8763 | D37: Nabtrade + Equate restricted/available
A38: Share portfolio growth rate | B38: 0.07 | D38: Conservative long-run net of tax
A39: Annual new investment (from surplus) | B39: 0 | D39: Set once investment property decision made
A41: SCHOOL FEES
A42: School fees — start year | B42: 2027 | D42: Liam starts St Kevin's Year 7
A43: School fees — first year cost | B43: 37596 | D43: Yr 7 2027, from actual St Kevin's schedule + levies
A44: School fees — annual escalation | B44: 0.04 | D44: Private school fee inflation avg
A45: School fees — number of years | B45: 6 | D45: Year 7–12 inclusive
...

Sheet 10-Year Projection
A1: JAMES & SUE — 10-YEAR HOUSEHOLD FINANCIAL PROJECTION
A2: Reflects ACTUAL repayments ($750/wk both loans) and offset inflows as at 29 Jul 2026. Change inputs on the Assumptions tab.
B3: 2026 | C3: 2027 | D3: 2028 | E3: 2029 | F3: 2030 | G3: 2031 | H3: 2032 | I3: 2033 | J3: 2034 | K3: 2035
A4: St Kevin's fee years | C4: Yr 7 | D4: Yr 8 | E4: Yr 9 | F4: Yr 10 | G4: Yr 11 | H4: Yr 12
A5: INCOME
A6: James — base salary | B6: =Assumptions!B5 -> 190000 | C6: =B6*(1+Assumptions!B10) -> 195700 | D6: =C6*(1+Assumptions!B10) -> 201571 | E6: =D6*(1+Assumptions!B10) -> 207618.13 | F6: =E6*(1+Assumptions!B10) -> 213846.67 | G6: =F6*(1+Assumptions!B10) -> 220262.07 | H6: =G6*(1+Assumptions!B10) -> 226869.94 | I6: =H6*(1+Assumptions!B10) -> 233676.03 | J6: =I6*(1+Assumptions!B10) -> 240686.32 | K6: =J6*(1+Assumptions!B10) -> 247906.9
A7: Sue — base salary (full-year rate) | B7: =Assumptions!B6 -> 200000 | C7: =B7*(1+Assumptions!B10)*Assumptions!B82 -> 206000 | D7: =C7*(1+Assumptions!B10) -> 212180 | E7: =D7*(1+Assumptions!B10) -> 218545.4 | F7: =E7*(1+Assumptions!B10) -> 225101.76 | G7: =F7*(1+Assumptions!B10) -> 231854.81 | H7: =G7*(1+Assumptions!B10) -> 238810.46 | I7: =H7*(1+Assumptions!B10) -> 245974.77 | J7: =I7*(1+Assumptions!B10) -> 253354.02 | K7: =J7*(1+Assumptions!B10) -> 260954.64
A8: Sue — salary lost during gap (2027) | B8: =0 -> 0 | C8: =-C7*Assumptions!B81/12 -> -68666.667 | D8: =0 -> 0 | E8: =0 -> 0 | F8: =0 -> 0 | G8: =0 -> 0 | H8: =0 -> 0 | I8: =0 -> 0 | J8: =0 -> 0 | K8: =0 -> 0
A9: Sue — redundancy (net of tax) | B9: =IF(2026=Assumptions!B62,MIN(Assumptions!B61,Assumptions!B64+Assumptions!B63*Assumptions!B65)+MAX(0,Assumptions!B61-(Assumptions!B64+Assumptions!B63*Assumptions!B65))*0.68,0) -> 0 | C9: =IF(2027=Assumptions!B62,MIN(Assumptions!B61,Assumptions!B64+Assumptions!B63*Assumptions!B65)+MAX(0,Assumptions!B61-(Assumptions!B64+Assumptions!B63*Assumptions!B65))*0.68,0) -> 65639.04 | D9: =IF(2028=Assumptions!B62,MIN(Assumptions!B61,Assumptions!B64+Assumptions!B63*Assumptions!B65)+MAX(0,Assumptions!B61-(Assumptions!B64+Assumptions!B63*Assumptions!B65))*0.68,0) -> 0 | E9: =IF(2029=Assumptions!B62,MIN(Assumptions!B61,Assumptions!B64+Assumptions!B63*Assumptions!B65)+MAX(0,Assumptions!B61-(Assumptions!B64+Assumptions!B63*Assumptions!B65))*0.68,0) -> 0 | F9: =IF(2030=Assumptions!B62,MIN(Assumptions!B61,Assumptions!B64+Assumptions!B63*Assumptions!B65)+MAX(0,Assumptions!B61-(Assumptions!B64+Assumptions!B63*Assumptions!B65))*0.68,0) -> 0 | G9: =IF(2031=Assumptions!B62,MIN(Assumptions!B61,Assumptions!B64+Assumptions!B63*Assumptions!B65)+MAX(0,Assumptions!B61-(Assumptions!B64+Assumptions!B63*Assumptions!B65))*0.68,0) -> 0 | H9: =IF(2032=Assumptions!B62,MIN(Assumptions!B61,Assumptions!B64+Assumptions!B63*Assumptions!B65)+MAX(0,Assumptions!B61-(Assumptions!B64+Assumptions!B63*Assumptions!B65))*0.68,0) -> 0 | I9: =IF(2033=Assumptions!B62,MIN(Assumptions!B61,Assumptions!B64+Assumptions!B63*Assumptions!B65)+MAX(0,Assumptions!B61-(Assumptions!B64+Assumptions!B63*Assumptions!B65))*0.68,0) -> 0 | J9: =IF(2034=Assumptions!B62,MIN(Assumptions!B61,Assumptions!B64+Assumptions!B63*Assumptions!B65)+MAX(0,Assumptions!B61-(Assumptions!B64+Assumptions!B63*Assumptions!B65))*0.68,0) -> 0 | K9: =IF(2035=Assumptions!B62,MIN(Assumptions!B61,Assumptions!B64+Assumptions!B63*Assumptions!B65)+MAX(0,Assumptions!B61-(Assumptions!B64+Assumptions!B63*Assumptions!B65))*0.68,0) -> 0
A10: James — expected bonus | B10: =B6*Assumptions!B8*Assumptions!B9 -> 22800 | C10: =C6*Assumptions!B8*Assumptions!B9 -> 23484 | D10: =D6*Assumptions!B8*Assumptions!B9 -> 24188.52 | E10: =E6*Assumptions!B8*Assumptions!B9 -> 24914.176 | F10: =F6*Assumptions!B8*Assumptions!B9 -> 25661.601 | G10: =G6*Assumptions!B8*Assumptions!B9 -> 26431.449 | H10: =H6*Assumptions!B8*Assumptions!B9 -> 27224.392 | I10: =I6*Assumptions!B8*Assumptions!B9 -> 28041.124 | J10: =J6*Assumptions!B8*Assumptions!B9 -> 28882.358 | K10: =K6*Assumptions!B8*Assumptions!B9 -> 29748.829
A11: Combined gross income | B11: =B6+B7+B8+B10 -> 412800 | C11: =C6+C7+C8+C10 -> 356517.33 | D11: =D6+D7+D8+D10 -> 437939.52 | E11: =E6+E7+E8+E10 -> 451077.71 | F11: =F6+F7+F8+F10 -> 464610.04 | G11: =G6+G7+G8+G10 -> 478548.34 | H11: =H6+H7+H8+H10 -> 492904.79 | I11: =I6+I7+I8+I10 -> 507691.93 | ... K11: =K6+K7+K8+K10 -> 538610.37
A12: James — employer super | B12: =(B6+B10)*Assumptions!B7 -> 26600 | C12: =(C6+C10)*Assumptions!B7 -> 27398 | D12: =(D6+D10)*Assumptions!B7 -> 28219.94 | E12: =(E6+E10)*Assumptions!B7 -> 29066.538 | F12: =(F6+F10)*Assumptions!B7 -> 29938.534 | G12: =(G6+G10)*Assumptions!B7 -> 30836.69 | H12: =(H6+H10)*Assumptions!B7 -> 31761.791 | I12: =(I6+I10)*Assumptions!B7 -> 32714.645 | J12: =(J6+J10)*Assumptions!B7 -> 33696.084 | K12: =(K6+K10)*Assumptions!B7 -> 34706.967
A13: Sue — employer super | B13: =(B7+B8)*Assumptions!B7 -> 25000 | C13: =(C7+C8)*Assumptions!B7 -> 17166.667 | D13: =(D7+D8)*Assumptions!B7 -> 26522.5 | E13: =(E7+E8)*Assumptions!B7 -> 27318.175 | F13: =(F7+F8)*Assumptions!B7 -> 28137.72 | G13: =(G7+G8)*Assumptions!B7 -> 28981.852 | H13: =(H7+H8)*Assumptions!B7 -> 29851.307 | I13: =(I7+I8)*Assumptions!B7 -> 30746.847 | J13: =(J7+J8)*Assumptions!B7 -> 31669.252 | K13: =(K7+K8)*Assumptions!B7 -> 32619.33
A14: James — net income (after tax) | B14: =(B6+B10)*0.666 -> 141724.8 | C14: =(C6+C10)*0.666 -> 145976.54 | D14: =(D6+D10)*0.666 -> 150355.84 | E14: =(E6+E10)*0.666 -> 154866.52 | F14: =(F6+F10)*0.666 -> 159512.51 | G14: =(G6+G10)*0.666 -> 164297.89 | H14: =(H6+H10)*0.666 -> 169226.82 | I14: =(I6+I10)*0.666 -> 174303.63 | ... K14: =(K6+K10)*0.666 -> 184918.72
A15: Sue — net income (incl redundancy) | B15: =(B7+B8)*0.666+B9 -> 133200 | C15: =(C7+C8)*0.666+C9 -> 157103.04 | D15: =(D7+D8)*0.666+D9 -> 141311.88 | E15: =(E7+E8)*0.666+E9 -> 145551.24 | F15: =(F7+F8)*0.666+F9 -> 149917.77 | G15: =(G7+G8)*0.666+G9 -> 154415.31 | H15: =(H7+H8)*0.666+H9 -> 159047.77 | I15: =(I7+I8)*0.666+I9 -> 163819.2 | ... K15: =(K7+K8)*0.666+K9 -> 173795.79
A16: Combined net income | B16: =B14+B15 -> 274924.8 | C16: =C14+C15 -> 303079.58 | D16: =D14+D15 -> 291667.72 | E16: =E14+E15 -> 300417.75 | F16: =F14+F15 -> 309430.28 | G16: =G14+G15 -> 318713.19 | H16: =H14+H15 -> 328274.59 | I16: =I14+I15 -> 338122.83 | ... K16: =K14+K15 -> 358714.51
A18: ANNUAL EXPENSES
A19: Alexander St — repayments (actual) | B19: =(Assumptions!B17+Assumptions!B18)*12 -> 39000 | C19: =(Assumptions!B17+Assumptions!B18)*12 -> 39000 | D19: =(Assumptions!B17+Assumptions!B18)*12 -> 39000 | E19: =(Assumptions!B17+Assumptions!B18)*12 -> 39000 | F19: =(Assumptions!B17+Assumptions!B18)*12 -> 39000 | G19: =(Assumptions!B17+Assumptions!B18)*12 -> 39000 | H19: =(Assumptions!B17+Assumptions!B18)*12 -> 39000 | I19: =(Assumptions!B17+Assumptions!B18)*12 -> 39000 | J19: =(Assumptions!B17+Assumptions!B18)*12 -> 39000 | K19: =(Assumptions!B17+Assumptions!B18)*12 -> 39000
A20: Walter St — repayments (actual) | B20: =(Assumptions!B24+Assumptions!B75)*12 -> 39000 | C20: =(Assumptions!B24+Assumptions!B75)*12 -> 39000 | D20: =(Assumptions!B24+Assumptions!B75)*12 -> 39000 | E20: =(Assumptions!B24+Assumptions!B75)*12 -> 39000 | F20: =(Assumptions!B24+Assumptions!B75)*12 -> 39000 | G20: =(Assumptions!B24+Assumptions!B75)*12 -> 39000 | H20: =(Assumptions!B24+Assumptions!B75)*12 -> 39000 | I20: =(Assumptions!B24+Assumptions!B75)*12 -> 39000 | J20: =(Assumptions!B24+Assumptions!B75)*12 -> 39000 | K20: =(Assumptions!B24+Assumptions!B75)*12 -> 39000
A21: Walter St — loan service fee | B21: =Assumptions!B76*12 -> 96 | C21: =Assumptions!B76*12 -> 96 | D21: =Assumptions!B76*12 -> 96 | E21: =Assumptions!B76*12 -> 96 | F21: =Assumptions!B76*12 -> 96 | G21: =Assumptions!B76*12 -> 96 | H21: =Assumptions!B76*12 -> 96 | I21: =Assumptions!B76*12 -> 96 | J21: =Assumptions!B76*12 -> 96 | K21: =Assumptions!B76*12 -> 96
A22: School fees — St Kevin's | B22: =IF(AND(2026>=Assumptions!B42,2026<Assumptions!B42+Assumptions!B45),Assumptions!B43*(1+Assumptions!B44)^(2026-Assumptions!B42),0) -> 0 | C22: =IF(AND(2027>=Assumptions!B42,2027<Assumptions!B42+Assumptions!B45),Assumptions!B43*(1+Assumptions!B44)^(2027-Assumptions!B42),0) -> 37596 | D22: =IF(AND(2028>=Assumptions!B42,2028<Assumptions!B42+Assumptions!B45),Assumptions!B43*(1+Assumptions!B44)^(2028-Assumptions!B42),0) -> 39099.84 | E22: =IF(AND(2029>=Assumptions!B42,2029<Assumptions!B42+Assumptions!B45),Assumptions!B43*(1+Assumptions!B44)^(2029-Assumptions!B42),0) -> 40663.834 | F22: =IF(AND(2030>=Assumptions!B42,2030<Assumptions!B42+Assumptions!B45),Assumptions!B43*(1+Assumptions!B44)^(2030-Assumptions!B42),0) -> 42290.387 | G22: =IF(AND(2031>=Assumptions!B42,2031<Assumptions!B42+Assumptions!B45),Assumptions!B43*(1+Assumptions!B44)^(2031-Assumptions!B42),0) -> 43982.002 | H22: =IF(AND(2032>=Assumptions!B42,2032<Assumptions!B42+Assumptions!B45),Assumptions!B43*(1+Assumptions!B44)^(2032-Assumptions!B42),0) -> 45741.283 | I22: =IF(AND(2033>=Assumptions!B42,2033<Assumptions!B42+Assumptions!B45),Assumptions!B43*(1+Assumptions!B44)^(2033-Assumptions!B42),0) -> 0 | J22: =IF(AND(2034>=Assumptions!B42,2034<Assumptions!B42+Assumptions!B45),Assumptions!B43*(1+Assumptions!B44)^(2034-Assumptions!B42),0) -> 0 | K22: =IF(AND(2035>=Assumptions!B42,2035<Assumptions!B42+Assumptions!B45),Assumptions!B43*(1+Assumptions!B44)^(2035-Assumptions!B42),0) -> 0
A23: Living expenses (CC + other) | B23: =(Assumptions!B48+Assumptions!B49) -> 110700 | C23: =B23*(1+Assumptions!B50) -> 114021 | D23: =C23*(1+Assumptions!B50) -> 117441.63 | E23: =D23*(1+Assumptions!B50) -> 120964.88 | F23: =E23*(1+Assumptions!B50) -> 124593.83 | G23: =F23*(1+Assumptions!B50) -> 128331.64 | H23: =G23*(1+Assumptions!B50) -> 132181.59 | I23: =H23*(1+Assumptions!B50) -> 136147.04 | J23: =I23*(1+Assumptions!B50) -> 140231.45 | K23: =J23*(1+Assumptions!B50) -> 144438.39
A24: Contingency & one-off costs | B24: =Assumptions!B68+Assumptions!B69 -> 13000 | C24: =Assumptions!B68+Assumptions!B70 -> 8000 | D24: =Assumptions!B68+Assumptions!B71 -> 8000 | E24: =Assumptions!B68 -> 8000 | F24: =Assumptions!B68 -> 8000 | G24: =Assumptions!B68 -> 8000 | H24: =Assumptions!B68 -> 8000 | I24: =Assumptions!B68 -> 8000 | J24: =Assumptions!B68 -> 8000 | K24: =Assumptions!B68 -> 8000
A25: Total annual expenses | B25: =B19+B20+B21+B22+B23+B24 -> 201796 | C25: =C19+C20+C21+C22+C23+C24 -> 237713 | D25: =D19+D20+D21+D22+D23+D24 -> 242637.47 | E25: =E19+E20+E21+E22+E23+E24 -> 247724.71 | F25: =F19+F20+F21+F22+F23+F24 -> 252980.21 | G25: =G19+G20+G21+G22+G23+G24 -> 258409.64 | H25: =H19+H20+H21+H22+H23+H24 -> 264018.87 | I25: =I19+I20+I21+I22+I23+I24 -> 222243.04 | ... K25: =K19+K20+K21+K22+K23+K24 -> 230534.39
A26: Annual surplus / (deficit) | B26: =B16-B25 -> 73128.8 | C26: =C16-C25 -> 65366.584 | D26: =D16-D25 -> 49030.25 | E26: =E16-E25 -> 52693.039 | F26: =F16-F25 -> 56450.072 | G26: =G16-G25 -> 60303.551 | H26: =H16-H25 -> 64255.717 | I26: =I16-I25 -> 115879.79 | ... K26: =K16-K25 -> 128180.12
A28: MORTGAGE BALANCES (GROSS)
A29: Alexander St — loan balance | B29: =Assumptions!B15 -> 170106 | C29: =MAX(0,B29*(1+Assumptions!B16/12)^12-(Assumptions!B17+Assumptions!B18)*12) -> 141400.2 | D29: =MAX(0,C29*(1+Assumptions!B16/12)^12-(Assumptions!B17+Assumptions!B18)*12) -> 110957.22 | E29: =MAX(0,D29*(1+Assumptions!B16/12)^12-(Assumptions!B17+Assumptions!B18)*12) -> 78671.948 | F29: =MAX(0,E29*(1+Assumptions!B16/12)^12-(Assumptions!B17+Assumptions!B18)*12) -> 44432.888 | G29: =MAX(0,F29*(1+Assumptions!B16/12)^12-(Assumptions!B17+Assumptions!B18)*12) -> 8121.8043 | H29: =MAX(0,G29*(1+Assumptions!B16/12)^12-(Assumptions!B17+Assumptions!B18)*12) -> 0 | I29: =MAX(0,H29*(1+Assumptions!B16/12)^12-(Assumptions!B17+Assumptions!B18)*12) -> 0 | J29: =MAX(0,I29*(1+Assumptions!B16/12)^12-(Assumptions!B17+Assumptions!B18)*12) -> 0 | K29: =MAX(0,J29*(1+Assumptions!B16/12)^12-(Assumptions!B17+Assumptions!B18)*12) -> 0
A30: Walter St — loan balance | B30: =Assumptions!B22 -> 459344 | C30: =MAX(0,B30*(1+Assumptions!B23/12)^12+Assumptions!B76*12-(Assumptions!B24+Assumptions!B75)*12) -> 448722.81 | D30: =MAX(0,C30*(1+Assumptions!B23/12)^12+Assumptions!B76*12-(Assumptions!B24+Assumptions!B75)*12) -> 437447.65 | E30: =MAX(0,D30*(1+Assumptions!B23/12)^12+Assumptions!B76*12-(Assumptions!B24+Assumptions!B75)*12) -> 425478.25 | F30: =MAX(0,E30*(1+Assumptions!B23/12)^12+Assumptions!B76*12-(Assumptions!B24+Assumptions!B75)*12) -> 412771.88 | G30: =MAX(0,F30*(1+Assumptions!B23/12)^12+Assumptions!B76*12-(Assumptions!B24+Assumptions!B75)*12) -> 399283.14 | H30: =MAX(0,G30*(1+Assumptions!B23/12)^12+Assumptions!B76*12-(Assumptions!B24+Assumptions!B75)*12) -> 384963.87 | I30: =MAX(0,H30*(1+Assumptions!B23/12)^12+Assumptions!B76*12-(Assumptions!B24+Assumptions!B75)*12) -> 369762.94 | J30: =MAX(0,I30*(1+Assumptions!B23/12)^12+Assumptions!B76*12-(Assumptions!B24+Assumptions!B75)*12) -> 353626.05 | K30: =MAX(0,J30*(1+Assumptions!B23/12)^12+Assumptions!B76*12-(Assumptions!B24+Assumptions!B75)*12) -> 336495.57
A31: Total loan balances | B31: =B29+B30 -> 629450 | C31: =C29+C30 -> 590123.01 | D31: =D29+D30 -> 548404.87 | E31: =E29+E30 -> 504150.2 | F31: =F29+F30 -> 457204.76 | G31: =G29+G30 -> 407404.94 | H31: =H29+H30 -> 384963.87 | I31: =I29+I30 -> 369762.94 | ... K31: =K29+K30 -> 336495.57
A33: OFFSET ACCOUNTS
A34: Alexander St offset | B34: =Assumptions!B19 -> 17350 | C34: =MIN(C29,B34+Assumptions!B77) -> 43350 | D34: =MIN(D29,C34+Assumptions!B77) -> 69350 | E34: =MIN(E29,D34+Assumptions!B77) -> 78671.948 | F34: =MIN(F29,E34+Assumptions!B77) -> 44432.888 | G34: =MIN(G29,F34+Assumptions!B77) -> 8121.8043 | H34: =MIN(H29,G34+Assumptions!B77) -> 0 | I34: =MIN(I29,H34+Assumptions!B77) -> 0 | J34: =MIN(J29,I34+Assumptions!B77) -> 0 | K34: =MIN(K29,J34+Assumptions!B77) -> 0
A35: Walter St offset (receives all surplus) | B35: =Assumptions!B25 -> 200014 | C35: =MAX(0,B35+C26+MAX(0,B34+Assumptions!B77-C29)) -> 265380.58 | D35: =MAX(0,C35+D26+MAX(0,C34+Assumptions!B77-D29)) -> 314410.83 | E35: =MAX(0,D35+E26+MAX(0,D34+Assumptions!B77-E29)) -> 383781.93 | F35: =MAX(0,E35+F26+MAX(0,E34+Assumptions!B77-F29)) -> 500471.06 | G35: =MAX(0,F35+G26+MAX(0,F34+Assumptions!B77-G29)) -> 623085.69 | H35: =MAX(0,G35+H26+MAX(0,G34+Assumptions!B77-H29)) -> 721463.21 | I35: =MAX(0,H35+I26+MAX(0,H34+Assumptions!B77-I29)) -> 863343 | J35: =MAX(0,I35+J26+MAX(0,I34+Assumptions!B77-J29)) -> 1011282.1 | K35: =MAX(0,J35+K26+MAX(0,J34+Assumptions!B77-K29)) -> 1165462.2
A36: Combined offsets | B36: =B34+B35 -> 217364 | C36: =C34+C35 -> 308730.58 | D36: =D34+D35 -> 383760.83 | E36: =E34+E35 -> 462453.87 | F36: =F34+F35 -> 544903.95 | G36: =G34+G35 -> 631207.5 | H36: =H34+H35 -> 721463.21 | I36: =I34+I35 -> 863343 | ... K36: =K34+K35 -> 1165462.2
A37: Alexander St — NET debt | B37: =B29-B34 -> 152756 | C37: =C29-C34 -> 98050.196 | D37: =D29-D34 -> 41607.221 | E37: =E29-E34 -> 0 | F37: =F29-F34 -> 0 | G37: =G29-G34 -> 0 | H37: =H29-H34 -> 0 | I37: =I29-I34 -> 0 | ... K37: =K29-K34 -> 0
A38: Walter St — NET debt | B38: =B30-B35 -> 259330 | C38: =C30-C35 -> 183342.23 | D38: =D30-D35 -> 123036.82 | E38: =E30-E35 -> 41696.329 | F38: =F30-F35 -> -87699.181 | G38: =G30-G35 -> -223802.55 | H38: =H30-H35 -> -336499.34 | I38: =I30-I35 -> -493580.07 | ... K38: =K30-K35 -> -828966.61
A39: COMBINED NET DEBT | B39: =B37+B38 -> 412086 | C39: =C37+C38 -> 281392.42 | D39: =D37+D38 -> 164644.04 | E39: =E37+E38 -> 41696.329 | F39: =F37+F38 -> -87699.181 | G39: =G37+G38 -> -223802.55 | H39: =H37+H38 -> -336499.34 | I39: =I37+I38 -> -493580.07 | ... K39: =K37+K38 -> -828966.61
A40: Offset saturation status | B40: =IF(B39<=0,"BOTH SATURATED",IF(B37<=0,"Alex saturated","OK")) -> OK | C40: =IF(C39<=0,"BOTH SATURATED",IF(C37<=0,"Alex saturated","OK")) -> OK | D40: =IF(D39<=0,"BOTH SATURATED",IF(D37<=0,"Alex saturated","OK")) -> OK | E40: =IF(E39<=0,"BOTH SATURATED",IF(E37<=0,"Alex saturated","OK")) -> Alex saturated | F40: =IF(F39<=0,"BOTH SATURATED",IF(F37<=0,"Alex saturated","OK")) -> BOTH SATURATED | G40: =IF(G39<=0,"BOTH SATURATED",IF(G37<=0,"Alex saturated","OK")) -> BOTH SATURATED | H40: =IF(H39<=0,"BOTH SATURATED",IF(H37<=0,"Alex saturated","OK")) -> BOTH SATURATED | I40: =IF(I39<=0,"BOTH SATURATED",IF(I37<=0,"Alex saturated","OK")) -> BOTH SATURATED | ... K40: =IF(K39<=0,"BOTH SATURATED",IF(K37<=0,"Alex saturated","OK")) -> BOTH SATURATED
A42: PROPERTY VALUES
A43: Alexander St — value | B43: =Assumptions!B13 -> 900000 | C43: =B43*(1+Assumptions!B14) -> 936000 | D43: =C43*(1+Assumptions!B14) -> 973440 | E43: =D43*(1+Assumptions!B14) -> 1012377.6 | F43: =E43*(1+Assumptions!B14) -> 1052872.7 | G43: =F43*(1+Assumptions!B14) -> 1094987.6 | H43: =G43*(1+Assumptions!B14) -> 1138787.1 | I43: =H43*(1+Assumptions!B14) -> 1184338.6 | J43: =I43*(1+Assumptions!B14) -> 1231712.1 | K43: =J43*(1+Assumptions!B14) -> 1280980.6
A44: Walter St — value | B44: =Assumptions!B20 -> 800000 | C44: =B44*(1+Assumptions!B21) -> 832000 | D44: =C44*(1+Assumptions!B21) -> 865280 | E44: =D44*(1+Assumptions!B21) -> 899891.2 | F44: =E44*(1+Assumptions!B21) -> 935886.85 | G44: =F44*(1+Assumptions!B21) -> 973322.32 | H44: =G44*(1+Assumptions!B21) -> 1012255.2 | I44: =H44*(1+Assumptions!B21) -> 1052745.4 | J44: =I44*(1+Assumptions!B21) -> 1094855.2 | K44: =J44*(1+Assumptions!B21) -> 1138649.4
...

Sheet Dashboard
A1: HOUSEHOLD FINANCIAL DASHBOARD
A2: Live links to the 10-Year Projection. Update inputs on the Assumptions tab.
B3: 2026 | C3: 2027 | D3: 2028 | E3: 2029 | F3: 2030 | G3: 2031 | H3: 2032 | I3: 2033 | J3: 2034 | K3: 2035
A4: NET WORTH
A5: Net worth | B5: ='10-Year Projection'!B60 -> 2233904 | C5: ='10-Year Projection'!C60 -> 2539348.4 | D5: ='10-Year Projection'!D60 -> 2850296.9 | E5: ='10-Year Projection'!E60 -> 3180410.8 | F5: ='10-Year Projection'!F60 -> 3530806.1 | G5: ='10-Year Projection'!G60 -> 3902669.1 | H5: ='10-Year Projection'!H60 -> 4266874.4 | I5: ='10-Year Projection'!I60 -> 4692268.3 | ... K5: ='10-Year Projection'!K60 -> 5619281.9
A6: Property equity | B6: ='10-Year Projection'!B46 -> 1070550 | C6: ='10-Year Projection'!C46 -> 1177877 | D6: ='10-Year Projection'!D46 -> 1290315.1 | E6: ='10-Year Projection'!E46 -> 1408118.6 | F6: ='10-Year Projection'!F46 -> 1531554.8 | G6: ='10-Year Projection'!G46 -> 1660905 | H6: ='10-Year Projection'!H46 -> 1766078.5 | I6: ='10-Year Projection'!I46 -> 1867321.1 | ... K6: ='10-Year Projection'!K46 -> 2083134.5
A7: Superannuation | B7: ='10-Year Projection'!B51 -> 798141 | C7: ='10-Year Projection'!C51 -> 894542.43 | D7: ='10-Year Projection'!D51 -> 1006948.7 | E7: ='10-Year Projection'!E51 -> 1128717 | F7: ='10-Year Projection'!F51 -> 1260547.5 | G7: ='10-Year Projection'!G51 -> 1403190.8 | H7: ='10-Year Projection'!H51 -> 1557451.3 | I7: ='10-Year Projection'!I51 -> 1724191.1 | ... K7: ='10-Year Projection'!K51 -> 2098870.9
A8: Shares | B8: ='10-Year Projection'!B54 -> 147849 | C8: ='10-Year Projection'!C54 -> 158198.43 | D8: ='10-Year Projection'!D54 -> 169272.32 | E8: ='10-Year Projection'!E54 -> 181121.38 | F8: ='10-Year Projection'!F54 -> 193799.88 | G8: ='10-Year Projection'!G54 -> 207365.87 | H8: ='10-Year Projection'!H54 -> 221881.48 | I8: ='10-Year Projection'!I54 -> 237413.19 | ... K8: ='10-Year Projection'!K54 -> 271814.36
A9: Offsets | B9: ='10-Year Projection'!B36 -> 217364 | C9: ='10-Year Projection'!C36 -> 308730.58 | D9: ='10-Year Projection'!D36 -> 383760.83 | E9: ='10-Year Projection'!E36 -> 462453.87 | F9: ='10-Year Projection'!F36 -> 544903.95 | G9: ='10-Year Projection'!G36 -> 631207.5 | H9: ='10-Year Projection'!H36 -> 721463.21 | I9: ='10-Year Projection'!I36 -> 863343 | ... K9: ='10-Year Projection'!K36 -> 1165462.2
A10: Loans (liability) | B10: ='10-Year Projection'!B31 -> 629450 | C10: ='10-Year Projection'!C31 -> 590123.01 | D10: ='10-Year Projection'!D31 -> 548404.87 | E10: ='10-Year Projection'!E31 -> 504150.2 | F10: ='10-Year Projection'!F31 -> 457204.76 | G10: ='10-Year Projection'!G31 -> 407404.94 | H10: ='10-Year Projection'!H31 -> 384963.87 | I10: ='10-Year Projection'!I31 -> 369762.94 | ... K10: ='10-Year Projection'!K31 -> 336495.57
A12: DEBT & OFFSET SATURATION
A13: Alexander St offset | B13: ='10-Year Projection'!B34 -> 17350 | C13: ='10-Year Projection'!C34 -> 43350 | D13: ='10-Year Projection'!D34 -> 69350 | E13: ='10-Year Projection'!E34 -> 78671.948 | F13: ='10-Year Projection'!F34 -> 44432.888 | G13: ='10-Year Projection'!G34 -> 8121.8043 | H13: ='10-Year Projection'!H34 -> 0 | I13: ='10-Year Projection'!I34 -> 0 | ... K13: ='10-Year Projection'!K34 -> 0
A14: Walter St offset | B14: ='10-Year Projection'!B35 -> 200014 | C14: ='10-Year Projection'!C35 -> 265380.58 | D14: ='10-Year Projection'!D35 -> 314410.83 | E14: ='10-Year Projection'!E35 -> 383781.93 | F14: ='10-Year Projection'!F35 -> 500471.06 | G14: ='10-Year Projection'!G35 -> 623085.69 | H14: ='10-Year Projection'!H35 -> 721463.21 | I14: ='10-Year Projection'!I35 -> 863343 | ... K14: ='10-Year Projection'!K35 -> 1165462.2
A15: Alexander St NET debt | B15: ='10-Year Projection'!B37 -> 152756 | C15: ='10-Year Projection'!C37 -> 98050.196 | D15: ='10-Year Projection'!D37 -> 41607.221 | E15: ='10-Year Projection'!E37 -> 0 | F15: ='10-Year Projection'!F37 -> 0 | G15: ='10-Year Projection'!G37 -> 0 | H15: ='10-Year Projection'!H37 -> 0 | I15: ='10-Year Projection'!I37 -> 0 | ... K15: ='10-Year Projection'!K37 -> 0
A16: Walter St NET debt | B16: ='10-Year Projection'!B38 -> 259330 | C16: ='10-Year Projection'!C38 -> 183342.23 | D16: ='10-Year Projection'!D38 -> 123036.82 | E16: ='10-Year Projection'!E38 -> 41696.329 | F16: ='10-Year Projection'!F38 -> -87699.181 | G16: ='10-Year Projection'!G38 -> -223802.55 | H16: ='10-Year Projection'!H38 -> -336499.34 | I16: ='10-Year Projection'!I38 -> -493580.07 | ... K16: ='10-Year Projection'!K38 -> -828966.61
A17: Combined NET debt | B17: ='10-Year Projection'!B39 -> 412086 | C17: ='10-Year Projection'!C39 -> 281392.42 | D17: ='10-Year Projection'!D39 -> 164644.04 | E17: ='10-Year Projection'!E39 -> 41696.329 | F17: ='10-Year Projection'!F39 -> -87699.181 | G17: ='10-Year Projection'!G39 -> -223802.55 | H17: ='10-Year Projection'!H39 -> -336499.34 | I17: ='10-Year Projection'!I39 -> -493580.07 | ... K17: ='10-Year Projection'!K39 -> -828966.61
A18: Saturation status | B18: ='10-Year Projection'!B40 -> OK | C18: ='10-Year Projection'!C40 -> OK | D18: ='10-Year Projection'!D40 -> OK | E18: ='10-Year Projection'!E40 -> Alex saturated | F18: ='10-Year Projection'!F40 -> BOTH SATURATED | G18: ='10-Year Projection'!G40 -> BOTH SATURATED | H18: ='10-Year Projection'!H40 -> BOTH SATURATED | I18: ='10-Year Projection'!I40 -> BOTH SATURATED | ... K18: ='10-Year Projection'!K40 -> BOTH SATURATED
A20: CASH FLOW
A21: Net income | B21: ='10-Year Projection'!B16 -> 274924.8 | C21: ='10-Year Projection'!C16 -> 303079.58 | D21: ='10-Year Projection'!D16 -> 291667.72 | E21: ='10-Year Projection'!E16 -> 300417.75 | F21: ='10-Year Projection'!F16 -> 309430.28 | G21: ='10-Year Projection'!G16 -> 318713.19 | H21: ='10-Year Projection'!H16 -> 328274.59 | I21: ='10-Year Projection'!I16 -> 338122.83 | ... K21: ='10-Year Projection'!K16 -> 358714.51
A22: Total expenses | B22: ='10-Year Projection'!B25 -> 201796 | C22: ='10-Year Projection'!C25 -> 237713 | D22: ='10-Year Projection'!D25 -> 242637.47 | E22: ='10-Year Projection'!E25 -> 247724.71 | F22: ='10-Year Projection'!F25 -> 252980.21 | G22: ='10-Year Projection'!G25 -> 258409.64 | H22: ='10-Year Projection'!H25 -> 264018.87 | I22: ='10-Year Projection'!I25 -> 222243.04 | ... K22: ='10-Year Projection'!K25 -> 230534.39
A23: School fees | B23: ='10-Year Projection'!B22 -> 0 | C23: ='10-Year Projection'!C22 -> 37596 | D23: ='10-Year Projection'!D22 -> 39099.84 | E23: ='10-Year Projection'!E22 -> 40663.834 | F23: ='10-Year Projection'!F22 -> 42290.387 | G23: ='10-Year Projection'!G22 -> 43982.002 | H23: ='10-Year Projection'!H22 -> 45741.283 | I23: ='10-Year Projection'!I22 -> 0 | ... K23: ='10-Year Projection'!K22 -> 0
A24: Annual surplus | B24: ='10-Year Projection'!B26 -> 73128.8 | C24: ='10-Year Projection'!C26 -> 65366.584 | D24: ='10-Year Projection'!D26 -> 49030.25 | E24: ='10-Year Projection'!E26 -> 52693.039 | F24: ='10-Year Projection'!F26 -> 56450.072 | G24: ='10-Year Projection'!G26 -> 60303.551 | H24: ='10-Year Projection'!H26 -> 64255.717 | I24: ='10-Year Projection'!I26 -> 115879.79 | ... K24: ='10-Year Projection'!K26 -> 128180.12
A25: Cumulative school fees | B25: ='10-Year Projection'!B57 -> 0 | C25: ='10-Year Projection'!C57 -> 37596 | D25: ='10-Year Projection'!D57 -> 76695.84 | E25: ='10-Year Projection'!E57 -> 117359.67 | F25: ='10-Year Projection'!F57 -> 159650.06 | G25: ='10-Year Projection'!G57 -> 203632.06 | H25: ='10-Year Projection'!H57 -> 249373.35 | I25: ='10-Year Projection'!I57 -> 249373.35 | ... K25: ='10-Year Projection'!K57 -> 249373.35
A27: SUPERANNUATION
A28: James | B28: ='10-Year Projection'!B49 -> 448141 | C28: ='10-Year Projection'!C49 -> 504429.35 | D28: ='10-Year Projection'!D49 -> 565405.44 | E28: ='10-Year Projection'!E49 -> 631419.84 | F28: ='10-Year Projection'!F49 -> 702848.32 | G28: ='10-Year Projection'!G49 -> 780093.68 | H28: ='10-Year Projection'!H49 -> 863587.58 | I28: ='10-Year Projection'!I49 -> 953792.68 | ... K28: ='10-Year Projection'!K49 -> 1156355.1
A29: Sue | B29: ='10-Year Projection'!B50 -> 350000 | C29: ='10-Year Projection'!C50 -> 390113.08 | D29: ='10-Year Projection'!D50 -> 441543.21 | E29: ='10-Year Projection'!E50 -> 497297.12 | F29: ='10-Year Projection'!F50 -> 557699.17 | G29: ='10-Year Projection'!G50 -> 623097.11 | H29: ='10-Year Projection'!H50 -> 693863.67 | I29: ='10-Year Projection'!I50 -> 770398.38 | ... K29: ='10-Year Projection'!K50 -> 942515.8
A30: Combined | B30: ='10-Year Projection'!B51 -> 798141 | C30: ='10-Year Projection'!C51 -> 894542.43 | D30: ='10-Year Projection'!D51 -> 1006948.7 | E30: ='10-Year Projection'!E51 -> 1128717 | F30: ='10-Year Projection'!F51 -> 1260547.5 | G30: ='10-Year Projection'!G51 -> 1403190.8 | H30: ='10-Year Projection'!H51 -> 1557451.3 | I30: ='10-Year Projection'!I51 -> 1724191.1 | ... K30: ='10-Year Projection'!K51 -> 2098870.9

Sheet Spending Budget
A1: HOUSEHOLD SPENDING BUDGET — JAMES & SUE
A2: Blue cells = your budget targets (annual) | Monthly and weekly auto-calculate | Variance = Budget minus Actual
A3: Category | B3: Annual budget ($) | C3: Monthly ($) | D3: Weekly ($) | E3: James — weekly ($) | F3: Sue — weekly ($) | G3: Actual — last 12m ($) | H3: Variance ($) | I3: Notes / context
A4: WEEKLY PERSONAL ALLOWANCES AT A GLANCE — James (blue) and Sue (green)
A5: James weekly targets → | B5: Dining out: $115 | C5: Cafes: $32 | D5: Groceries: $98 | E5: Transport: $46 | F5: Subscriptions: $14
A6: Sue weekly targets → | B6: Dining out: $115 | C6: Cafes: $28 | D6: Groceries: $52 | E6: Transport: $40 | F6: Subscriptions: $14
A7: FOOD & DINING
A8: Dining out & restaurants | B8: 12000 | C8: =ROUND(B8/12,0) -> 1000 | D8: =ROUND(B8/52,0) -> 231 | E8: =ROUND(D8*0.5,0) -> 116 | F8: =ROUND(D8*0.5,0) -> 116 | G8: 22000 | H8: =IF(G8<>"",B8-G8,"") -> -10000 | I8: Split evenly — shared expense | Target $1,000/mth vs $1,800+ actual — biggest saving opp
A9: Cafes & coffee | B9: 3000 | C9: =ROUND(B9/12,0) -> 250 | D9: =ROUND(B9/52,0) -> 58 | E9: =ROUND(D9*0.5,0) -> 29 | F9: =ROUND(D9*0.5,0) -> 29 | G9: 4000 | H9: =IF(G9<>"",B9-G9,"") -> -1000 | I9: James slightly higher based on weekday pattern | Daily coffees x2 + weekend cafes — ~$58/wk target
A10: Takeaway & delivery | B10: 2400 | C10: =ROUND(B10/12,0) -> 200 | D10: =ROUND(B10/52,0) -> 46 | E10: =ROUND(D10*0.5,0) -> 23 | F10: =ROUND(D10*0.5,0) -> 23 | G10: 3500 | H10: =IF(G10<>"",B10-G10,"") -> -1100 | I10: Split evenly | Target $200/mth — currently ~$290
A11: Supermarkets & groceries | B11: 11960 | C11: =ROUND(B11/12,0) -> 997 | D11: =ROUND(B11/52,0) -> 230 | E11: =ROUND(D11*0.5,0) -> 115 | F11: =ROUND(D11*0.5,0) -> 115 | G11: 11200 | H11: =IF(G11<>"",B11-G11,"") -> 760 | I11: James ~$150/wk via Woolworths gift cards; Sue ~$80/wk + Happy Apple/Asian grocery | Gift cards don't show as grocery on statement — actual may be higher
A12: Alcohol & bottle shop | H12: =IF(E9<>"",B9-E9,"") -> 2971 | I12: Split evenly | Included in dining estimate — flag if tracked separately
A13: FOOD & DINING TOTAL | B13: =SUM(B8:B11) -> 29360 | C13: =SUM(C8:C11) -> 2447 | D13: =SUM(D8:D11) -> 565 | E13: =SUM(E8:E11) -> 283 | F13: =SUM(F8:F11) -> 283 | G13: =IFERROR(SUM(G8:G11),"") -> 40700 | H13: =SUMIF(G8:G11,"<>",B8:B11)-SUMIF(G8:G11,"<>",G8:G11) -> -11340
A15: HOUSING & PROPERTY
A16: Alexander St mortgage (min + extra) | B16: 39024 | C16: =ROUND(B16/12,0) -> 3252 | D16: =ROUND(B16/52,0) -> 750 | E16: =ROUND(D16*1,0) -> 750 | F16: =ROUND(D16*0,0) -> 0 | G16: 39024 | H16: =IF(G16<>"",B16-G16,"") -> 0 | I16: James only — his property | Fixed — $1,752 min + $1,500 extra × 12
A17: Walter St mortgage (minimum) | B17: 35796 | C17: =ROUND(B17/12,0) -> 2983 | D17: =ROUND(B17/52,0) -> 688 | E17: =ROUND(D17*0,0) -> 0 | F17: =ROUND(D17*1,0) -> 688 | G17: 35796 | H17: =IF(G17<>"",B17-G17,"") -> 0 | I17: Sue only — her property | Fixed — $2,983 × 12
A18: Council rates — Alexander St | B18: 2200 | C18: =ROUND(B18/12,0) -> 183 | D18: =ROUND(B18/52,0) -> 42 | E18: =ROUND(D18*1,0) -> 42 | F18: =ROUND(D18*0,0) -> 0 | H18: =IF(G18<>"",B18-G18,"") | I18: James only | Estimate — update with actual notice
A19: Council rates — Walter St | B19: 2200 | C19: =ROUND(B19/12,0) -> 183 | D19: =ROUND(B19/52,0) -> 42 | E19: =ROUND(D19*0,0) -> 0 | F19: =ROUND(D19*1,0) -> 42 | H19: =IF(G19<>"",B19-G19,"") | I19: Sue only | Estimate — update with actual notice
A20: Home & contents insurance (both properties) | B20: 3600 | C20: =ROUND(B20/12,0) -> 300 | D20: =ROUND(B20/52,0) -> 69 | E20: =ROUND(D20*0.5,0) -> 35 | F20: =ROUND(D20*0.5,0) -> 35 | H20: =IF(G20<>"",B20-G20,"") | I20: Split evenly | Estimate — review against actual policy premium
A21: Home maintenance & repairs (annual contingency) | B21: 8000 | C21: =ROUND(B21/12,0) -> 667 | D21: =ROUND(B21/52,0) -> 154 | E21: =ROUND(D21*0.5,0) -> 77 | F21: =ROUND(D21*0.5,0) -> 77 | H21: =IF(G21<>"",B21-G21,"") | I21: Split evenly | Budgeted contingency — incl fence, appliances, garden
A22: Body corp / strata (if applicable) | H22: =IF(E19<>"",B19-E19,"") -> 2200 | I22: Confirmed not applicable — both properties are houses
A23: HOUSING TOTAL | B23: =SUM(B16:B21) -> 90820 | C23: =SUM(C16:C21) -> 7568 | D23: =SUM(D16:D21) -> 1745 | E23: =SUM(E16:E21) -> 904 | F23: =SUM(F16:F21) -> 842 | G23: =IFERROR(SUM(G16:G21),"") -> 74820 | H23: =SUMIF(G16:G21,"<>",B16:B21)-SUMIF(G16:G21,"<>",G16:G21) -> 0
A25: INSURANCE & HEALTH
A26: Private health insurance (BUPA) | B26: 3600 | C26: =ROUND(B26/12,0) -> 300 | D26: =ROUND(B26/52,0) -> 69 | E26: =ROUND(D26*0.5,0) -> 35 | F26: =ROUND(D26*0.5,0) -> 35 | G26: 4537 | H26: =IF(G26<>"",B26-G26,"") -> -937 | I26: Family policy — split evenly | Currently $378/mth — budget assumes negotiated down
A27: Life / income protection insurance | B27: 2400 | C27: =ROUND(B27/12,0) -> 200 | D27: =ROUND(B27/52,0) -> 46 | E27: =ROUND(D27*0.5,0) -> 23 | F27: =ROUND(D27*0.5,0) -> 23 | H27: =IF(G27<>"",B27-G27,"") | I27: Individual policies — each bears own | Estimate — critical given no formal estate docs
A28: Car insurance — one shared vehicle | B28: 1200 | C28: =ROUND(B28/12,0) -> 100 | D28: =ROUND(B28/52,0) -> 23 | E28: =ROUND(D28*0.5,0) -> 12 | F28: =ROUND(D28*0.5,0) -> 12 | H28: =IF(G28<>"",B28-G28,"") | I28: One car — updated from prior 2-car estimate
A29: Travel insurance (annual multi-trip) | B29: 650 | C29: =ROUND(B29/12,0) -> 54 | D29: =ROUND(B29/52,0) -> 13 | E29: =ROUND(D29*0.5,0) -> 7 | F29: =ROUND(D29*0.5,0) -> 7 | H29: =IF(G29<>"",B29-G29,"") | I29: Family policy — split evenly | Replace lost NAB card cover — action item #2
A30: Pharmacy & medical out-of-pocket | H30: =IF(G30<>"",B30-G30,"") | I30: $100/person/month — GP ~$60 out-of-pocket per visit + pharmacy. Update with actuals.
A31: INSURANCE & HEALTH TOTAL | B31: =SUM(B26:B29) -> 7850 | C31: =SUM(C26:C29) -> 654 | D31: =SUM(D26:D29) -> 151 | E31: =SUM(E26:E29) -> 77 | F31: =SUM(F26:F29) -> 77 | G31: =IFERROR(SUM(G26:G29),"") -> 4537 | H31: =SUMIF(G26:G29,"<>",B26:B29)-SUMIF(G26:G29,"<>",G26:G29) -> -937
A33: TRANSPORT
A34: Fuel — one shared car (~1 tank/month @ $70) | B34: 840 | C34: =ROUND(B34/12,0) -> 70 | D34: =ROUND(B34/52,0) -> 16 | E34: =ROUND(D34*0.5,0) -> 8 | F34: =ROUND(D34*0.5,0) -> 8 | H34: =IF(G34<>"",B34-G34,"") | I34: $70/tank × 12 months. Update if usage changes.
A35: Car servicing & maintenance | B35: 800 | C35: =ROUND(B35/12,0) -> 67 | D35: =ROUND(B35/52,0) -> 15 | E35: =ROUND(D35*0.5,0) -> 8 | F35: =ROUND(D35*0.5,0) -> 8 | H35: =IF(G35<>"",B35-G35,"") | I35: Older car — allow for unexpected repairs
A36: Registration — one vehicle | B36: 900 | C36: =ROUND(B36/12,0) -> 75 | D36: =ROUND(B36/52,0) -> 17 | E36: =ROUND(D36*0.5,0) -> 9 | F36: =ROUND(D36*0.5,0) -> 9 | H36: =IF(G36<>"",B36-G36,"") | I36: Update with actual Vic Roads amount
A37: Public transport — James (4 days/wk to office) | B37: 2912 | C37: =ROUND(B37/12,0) -> 243 | D37: =ROUND(B37/52,0) -> 56 | E37: =B37 -> 2912 | F37: 0 | H37: =IF(G37<>"",B37-G37,"") | I37: 4 days × 2 × $7 × 52wks. Vic Govt half-price to Dec 2026 saves ~$1,000 this year.
A38: Public transport — Sue (3 days/wk to city) | H38: =IF(G38<>"",B38-G38,"") | I38: 3 days × 2 × $7 × 52wks. Half-price to Dec 2026 saves ~$750 this year.
A39: Parking & tolls | H39: =IF(G39<>"",B39-G39,"") | I39: ~$20/wk — occasional parking only
A40: TRANSPORT TOTAL | B40: =SUM(B34:B39) -> 5452 | C40: =SUM(C34:C39) -> 455 | D40: =SUM(D34:D39) -> 104 | E40: =SUM(E34:E39) -> 2937 | F40: =SUM(F34:F39) -> 25 | G40: =IFERROR(SUM(G34:G39),"") -> 0 | H40: =SUMIF(G34:G39,"<>",B34:B39)-SUMIF(G34:G39,"<>",G34:G39) -> 0
A42: SUBSCRIPTIONS & TECHNOLOGY
A43: Streaming (Netflix / Disney+ / Stan — 1 active) | B43: 240 | C43: =ROUND(B42/12,0) -> 0 | D43: =ROUND(B42/52,0) -> 0 | E43: =ROUND(D43*0.5,0) -> 0 | F43: =ROUND(D43*0.5,0) -> 0 | G43: 816 | H43: =IF(G42<>"",B42-G42,"") | I43: Shared household | Budget for 1 service at a time — cancel unused
A44: AI tools (Claude / ChatGPT) | B44: 408 | C44: =ROUND(B43/12,0) -> 20 | D44: =ROUND(B43/52,0) -> 5 | E44: =ROUND(D44*0.5,0) -> 3 | F44: =ROUND(D44*0.5,0) -> 3 | G44: 816 | H44: =IF(G43<>"",B43-G43,"") -> -576 | I44: Review — one shared account may suffice
...
